Workbook

Sheet RO History Pulls Needed - 04082
A1: Record ID | B1: Deal Name | C1: RO History Progress | D1: RO History Jira Ticket | E1: SKAI Products | F1: DMS | G1: Company Name | H1: Long Org ID | I1: Company Status | J1: Onboarding Start Date | K1: Onboarding Complete Date (Text Offer) | L1: Onboarding Complete Date (Cycle Time) | M1: Associated Product | N1: Dealer Group | O1: Pipeline | P1: Deal Stage | Q1: Close Date | R1: Associated Company | S1: Deal owner | T1: Amount | U1: Renewal Terms | V1: Last Activity Date | W1: Associated Product IDs | X1: Associated Company IDs
A2: 57553807764 | B2: Bluebonnet Ford | C2: Incomplete | E2: Text Offer | F2: CDK | G2: =VLOOKUP($B2,'All companies w Org IDs'!$A:$B,1,FALSE) -> Bluebonnet Ford | H2: =VLOOKUP($B2,'All companies w Org IDs'!$A:$B,2,FALSE) -> 11f04e13-68ac-010c-bd24-126156369a47 | I2: =VLOOKUP($B2,'All companies w Org IDs'!$A:$E,5,FALSE) -> BILLING | J2: 46092 | K2: 46106 | M2: CDK DMS FEE - MONTHLY;CDK DMS FEE - ONE-TIME;SKAIVISION LITE (6 Month Renewal) | O2: SKAIVISION Customer Success | P2: Active - Healthy | Q2: 46086.637 | R2: Bluebonnet Ford | S2: Dan Dillingham | T2: 1544 | U2: 6 Months | V2: 46118.411 | W2: 2673134739;24539557269;2725210928 | X2: 27221073244
A3: 55113525641 | B3: Modern Nissan of Concord | C3: Incomplete | E3: Text Offer | F3: CDK | G3: =VLOOKUP(B3,'All companies w Org IDs'!$A:$B,1,FALSE) -> Modern Nissan of Concord | H3: =VLOOKUP($B3,'All companies w Org IDs'!$A:$B,2,FALSE) -> 11f106d2-3bbf-696c-b23b-0affcfc7e79f | I3: =VLOOKUP($B3,'All companies w Org IDs'!$A:$E,5,FALSE) -> BILLING | J3: 46065 | K3: 46076 | M3: SKAIVISION LITE (90 Day Renewal) ;CDK DMS FEE - ONE-TIME;CDK DMS FEE - MONTHLY | O3: SKAIVISION Customer Success | P3: Active - Healthy | Q3: 46062.573 | R3: Modern Nissan of Concord | S3: Blake Andreese | T3: 3188 | V3: 46113.375 | W3: 2725529266;24539557269;2673134739 | X3: 50251057419
A4: 54403326272 | B4: Modern Nissan of Lake Norman | C4: Incomplete | E4: Text Offer | F4: CDK | G4: =VLOOKUP(B4,'All companies w Org IDs'!$A:$B,1,FALSE) -> Modern Nissan of Lake Norman | H4: =VLOOKUP($B4,'All companies w Org IDs'!$A:$B,2,FALSE) -> 11f106d1-fa27-8336-b23b-0affcfc7e79f | I4: =VLOOKUP($B4,'All companies w Org IDs'!$A:$E,5,FALSE) -> BILLING | J4: 46064 | K4: 46073 | M4: CDK DMS FEE - MONTHLY;SKAIVISION LITE (90 Day Renewal) ;CDK DMS FEE - ONE-TIME | O4: SKAIVISION Customer Success | P4: Active - Healthy | Q4: 46062.573 | R4: Modern Nissan of Lake Norman | S4: Blake Andreese | T4: 1444 | V4: 46113.375 | W4: 2673134739;2725529266;24539557269 | X4: 49545926978
A5: 52389962250 | B5: Mercedes-Benz of Des Moines | C5: Incomplete | E5: Text Offer | F5: CDK | G5: =VLOOKUP(B5,'All companies w Org IDs'!$A:$B,1,FALSE) -> Mercedes-Benz of Des Moines | H5: =VLOOKUP($B5,'All companies w Org IDs'!$A:$B,2,FALSE) -> 11f0e050-4b7f-7e80-b23b-0affcfc7e79f | I5: =VLOOKUP($B5,'All companies w Org IDs'!$A:$E,5,FALSE) -> BILLING | J5: 46062 | K5: 46069 | M5: CDK DMS FEE - MONTHLY;CDK DMS FEE - ONE-TIME;SKAIVISION LITE (90 Day Renewal) | O5: SKAIVISION Customer Success | P5: Active - Healthy | Q5: 46013.676 | R5: Mercedes-Benz of Des Moines | S5: Dan Dillingham | T5: 3288 | U5: 3 Months | V5: 46113.375 | W5: 2673134739;24539557269;2725529266 | X5: 47619073066
A6: 51926068766 | B6: Curry Honda | C6: Incomplete | E6: Text Offer | F6: CDK | G6: =VLOOKUP(B6,'All companies w Org IDs'!$A:$B,1,FALSE) -> Curry Honda | H6: =VLOOKUP($B6,'All companies w Org IDs'!$A:$B,2,FALSE) -> 11f0fd24-e94b-8f4f-b23b-0affcfc7e79f | I6: =VLOOKUP($B6,'All companies w Org IDs'!$A:$E,5,FALSE) -> BILLING | J6: 46059 | K6: 46064 | M6: CDK DMS FEE - MONTHLY;SKAIVISION LITE (90 Day Renewal) ;CDK DMS FEE - ONE-TIME | O6: SKAIVISION Customer Success | P6: Active - Healthy | Q6: 46052.494 | R6: Curry Honda | S6: Blake Andreese | T6: 3449 | V6: 46120.655 | W6: 2673134739;2725529266;24539557269 | X6: 25569592395
A7: 54319879985 | B7: Bob Bell Chevrolet of BelAir | C7: Needs Jira Ticket | E7: Text Offer | F7: CDK | G7: =VLOOKUP(B7,'All companies w Org IDs'!$A:$B,1,FALSE) -> Bob Bell Chevrolet of BelAir | H7: =VLOOKUP($B7,'All companies w Org IDs'!$A:$B,2,FALSE) -> 11f0fe2c-aead-db73-b23b-0affcfc7e79f | I7: =VLOOKUP($B7,'All companies w Org IDs'!$A:$E,5,FALSE) -> BILLING | J7: 46055 | K7: 46076 | M7: CDK DMS FEE - MONTHLY;SKAIVISION LITE (90 Day Renewal) ;CDK DMS FEE - ONE-TIME | O7: SKAIVISION Customer Success | P7: Active - Healthy | Q7: 46052.53 | R7: Bob Bell Chevrolet of BelAir | S7: Tiffany Peeler (Deactivated User) | T7: 3488 | V7: 46113.376 | W7: 2673134739;2725529266;24539557269 | X7: 49483896328
A8: 54223767681 | B8: Bob Bell Chevrolet of Baltimore | C8: Incomplete | E8: Text Offer | F8: CDK | G8: =VLOOKUP(B8,'All companies w Org IDs'!$A:$B,1,FALSE) -> Bob Bell Chevrolet of Baltimore | H8: =VLOOKUP($B8,'All companies w Org IDs'!$A:$B,2,FALSE) -> 11f0fe2c-f939-2923-b23b-0affcfc7e79f | I8: =VLOOKUP($B8,'All companies w Org IDs'!$A:$E,5,FALSE) -> BILLING | J8: 46055 | K8: 46076 | M8: CDK DMS FEE - MONTHLY;SKAIVISION LITE (90 Day Renewal) ;CDK DMS FEE - ONE-TIME | O8: SKAIVISION Customer Success | P8: Active - Healthy | Q8: 46052.531 | R8: Bob Bell Chevrolet - Baltimore | S8: Tiffany Peeler (Deactivated User) | T8: 3488 | V8: 46113.376 | W8: 2673134739;2725529266;24539557269 | X8: 49265332262
A9: 54317303599 | B9: Bob Bell Hyundai / Ford | C9: Incomplete | E9: Text Offer | F9: CDK | G9: =VLOOKUP(B9,'All companies w Org IDs'!$A:$B,1,FALSE) -> Bob Bell Hyundai / Ford | H9: =VLOOKUP($B9,'All companies w Org IDs'!$A:$B,2,FALSE) -> 11f10070-01e2-3d8f-b23b-0affcfc7e79f | I9: =VLOOKUP($B9,'All companies w Org IDs'!$A:$E,5,FALSE) -> BILLING | J9: 46055 | K9: 46072 | M9: SKAIVISION LITE (90 Day Renewal) ;CDK DMS FEE - ONE-TIME;CDK DMS FEE - MONTHLY | O9: SKAIVISION Customer Success | P9: Active - Healthy | Q9: 46053.656 | R9: Bob Bell Hyundai / Ford | S9: Blake Andreese | T9: 1744 | V9: 46087.676 | W9: 2725529266;24539557269;2673134739 | X9: 49265332240
A10: 51379588423 | B10: Community Honda | C10: Incomplete | E10: Text Offer | F10: CDK | G10: =VLOOKUP(B10,'All companies w Org IDs'!$A:$B,1,FALSE) -> Community Honda | H10: =VLOOKUP($B10,'All companies w Org IDs'!$A:$B,2,FALSE) -> 11f0ed63-0b6a-cc88-b23b-0affcfc7e79f | I10: =VLOOKUP($B10,'All companies w Org IDs'!$A:$E,5,FALSE) -> BILLING | J10: 46055 | K10: 46062 | M10: CDK DMS FEE - MONTHLY;CDK DMS FEE - ONE-TIME;SKAIVISION LITE (90 Day Renewal) | O10: SKAIVISION Customer Success | P10: Active - Healthy | Q10: 46030.723 | R10: Community Honda | S10: Dan Dillingham | T10: 3488 | U10: 3 Months | V10: 46113.375 | W10: 2673134739;24539557269;2725529266 | X10: 46819639212
A11: 54105447249 | B11: Cocoa Hyundai | C11: Incomplete | E11: Text Offer | F11: CDK | G11: =VLOOKUP(B11,'All companies w Org IDs'!$A:$B,1,FALSE) -> Cocoa Hyundai | H11: =VLOOKUP($B11,'All companies w Org IDs'!$A:$B,2,FALSE) -> 11f0f585-d554-10e1-b23b-0affcfc7e79f | I11: =VLOOKUP($B11,'All companies w Org IDs'!$A:$E,5,FALSE) -> BILLING | J11: 46050 | K11: 46065 | M11: SKAIVISION LITE (6 Month Renewal);CDK DMS FEE - ONE-TIME;CDK DMS FEE - MONTHLY | O11: SKAIVISION Customer Success | P11: Active - Healthy | Q11: 46041.41 | R11: Cocoa Hyundai | S11: Mike Barnett | T11: 1944 | V11: 46113.652 | W11: 2725210928;24539557269;2673134739 | X11: 43633018786
A12: 54078383201 | B12: Coastal Hyundai / Genesis | C12: Incomplete | E12: Text Offer | F12: CDK | G12: =VLOOKUP(B12,'All companies w Org IDs'!$A:$B,1,FALSE) -> Coastal Hyundai / Genesis | H12: =VLOOKUP($B12,'All companies w Org IDs'!$A:$B,2,FALSE) -> 11f0f583-96c1-9f97-b23b-0affcfc7e79f | I12: =VLOOKUP($B12,'All companies w Org IDs'!$A:$E,5,FALSE) -> BILLING | J12: 46050 | K12: 46066 | M12: CDK DMS FEE - ONE-TIME;CDK DMS FEE - MONTHLY;SKAIVISION LITE (6 Month Renewal) | O12: SKAIVISION Customer Success | P12: Active - Healthy | Q12: 46041.41 | R12: Coastal Hyundai / Genesis | S12: Mike Barnett | T12: 3888 | V12: 46114.661 | W12: 24539557269;2673134739;2725210928 | X12: 48844147110
A13: 54353643176 | B13: Maxie Price Chevrolet | C13: Incomplete | E13: Text Offer | F13: CDK | G13: =VLOOKUP(B13,'All companies w Org IDs'!$A:$B,1,FALSE) -> Maxie Price Chevrolet | H13: =VLOOKUP($B13,'All companies w Org IDs'!$A:$B,2,FALSE) -> 11f0fad9-dd98-5cde-b23b-0affcfc7e79f | I13: =VLOOKUP($B13,'All companies w Org IDs'!$A:$E,5,FALSE) -> BILLING | J13: 46049 | K13: 46052 | O13: SKAIVISION Customer Success | P13: Active - Healthy | Q13: 46048.741 | R13: Maxie Price Chevrolet | S13: Blake Andreese | T13: 3639 | V13: 46115.646 | X13: 49510360659
A14: 54128052854 | B14: Capitol Nissan - Infiniti of San Jose | C14: Incomplete | E14: Text Offer | F14: CDK | G14: =VLOOKUP(B14,'All companies w Org IDs'!$A:$B,1,FALSE) -> Capitol Nissan - Infiniti of San Jose | H14: =VLOOKUP($B14,'All companies w Org IDs'!$A:$B,2,FALSE) -> 11f0fb84-6238-7c64-b23b-0affcfc7e79f | I14: =VLOOKUP($B14,'All companies w Org IDs'!$A:$E,5,FALSE) -> BILLING | J14: 46049 | K14: 46051 | M14: SKAIVISION LITE (12 Month Renewal) | O14: SKAIVISION Customer Success | P14: Active - Healthy | Q14: 46048.835 | R14: Capitol Nissan - Infiniti of San Jose | S14: Blake Andreese | T14: 3390 | U14: 3 Months | V14: 46113.376 | W14: 2725529267 | X14: 50163010395
A15: 53451042938 | B15: Sunbury Motors - Ford Hyundai | C15: Incomplete | E15: Text Offer | F15: CDK | G15: =VLOOKUP(B15,'All companies w Org IDs'!$A:$B,1,FALSE) -> Sunbury Motors - Ford Hyundai | H15: =VLOOKUP($B15,'All companies w Org IDs'!$A:$B,2,FALSE) -> 11f0f579-94b5-8a35-b23b-0affcfc7e79f | I15: =VLOOKUP($B15,'All companies w Org IDs'!$A:$E,5,FALSE) -> BILLING | J15: 46044 | K15: 46059 | M15: CDK DMS FEE - MONTHLY;SKAIVISION LITE (90 Day Renewal) ;CDK DMS FEE - ONE-TIME | O15: SKAIVISION Customer Success | P15: Active - Healthy | Q15: 46037.792 | R15: Sunbury Motors - Ford Hyundai;Sunbury Motor Company | S15: Blake Andreese | T15: 1544 | V15: 46112.458 | W15: 2673134739;2725529266;24539557269 | X15: 49265095565;43802318213
A16: 52994168464 | B16: Meade Lexus of Southfield | C16: Incomplete | E16: Text Offer | F16: CDK | G16: =VLOOKUP(B16,'All companies w Org IDs'!$A:$B,1,FALSE) -> Meade Lexus of Southfield | H16: =VLOOKUP($B16,'All companies w Org IDs'!$A:$B,2,FALSE) -> 11ee92fe-d4a0-3d23-b33f-0ada0ce51a25 | I16: =VLOOKUP($B16,'All companies w Org IDs'!$A:$E,5,FALSE) -> BILLING | J16: 46042 | K16: 46056 | M16: CDK DMS FEE - MONTHLY;CDK DMS FEE - ONE-TIME;SKAIVISION LITE (6 Month Renewal) | O16: SKAIVISION Customer Success | P16: Active - Healthy | Q16: 46034.601 | R16: Meade Lexus of Southfield | S16: Dan Dillingham | T16: 3488 | V16: 46119.413 | W16: 2673134739;24539557269;2725210928 | X16: 19421682585
A17: 53886972963 | B17: CDJR of Fort Myers | C17: Incomplete | E17: Text Offer | F17: CDK | G17: =VLOOKUP(B17,'All companies w Org IDs'!$A:$B,1,FALSE) -> CDJR of Fort Myers | H17: =VLOOKUP($B17,'All companies w Org IDs'!$A:$B,2,FALSE) -> 11f0f261-416c-5684-b23b-0affcfc7e79f | I17: =VLOOKUP($B17,'All companies w Org IDs'!$A:$E,5,FALSE) -> BILLING | J17: 46038 | K17: 46093 | M17: CDK DMS FEE - MONTHLY;SKAIVISION LITE (6 Month Renewal);CDK DMS FEE - ONE-TIME | O17: SKAIVISION Customer Success | P17: Active - Healthy | Q17: 46037.581 | R17: CDJR of Fort Myers | S17: Mike Barnett | T17: 3088 | V17: 46119.438 | W17: 2673134739;2725210928;24539557269 | X17: 48958490034
A18: 53886911126 | B18: Kia of Fort Myers | C18: Incomplete | E18: Text Offer | F18: CDK | G18: =VLOOKUP(B18,'All companies w Org IDs'!$A:$B,1,FALSE) -> Kia of Fort Myers | H18: =VLOOKUP($B18,'All companies w Org IDs'!$A:$B,2,FALSE) -> 11f0f261-a0b2-4cce-b23b-0affcfc7e79f | I18: =VLOOKUP($B18,'All companies w Org IDs'!$A:$E,5,FALSE) -> BILLING | J18: 46038 | K18: 46093 | M18: CDK DMS FEE - MONTHLY;SKAIVISION LITE (6 Month Renewal);CDK DMS FEE - ONE-TIME | N18: <a href="https://app.hubspot.com/contacts/22669654/record/0-2/48101501488 " target="_blank"> Bill Nero Auto Group </a> | O18: SKAIVISION Customer Success | P18: Active - Healthy | Q18: 46036.852 | R18: Kia of Fort Myers | S18: Mike Barnett | T18: 1544 | V18: 46094.436 | W18: 2673134739;2725210928;24539557269 | X18: 48327557201
A19: 46291879280 | B19: Hollingsworth Richards Ford | C19: Incomplete | E19: Text Offer | F19: CDK | G19: =VLOOKUP(B19,'All companies w Org IDs'!$A:$B,1,FALSE) -> Hollingsworth Richards Ford | H19: =VLOOKUP($B19,'All companies w Org IDs'!$A:$B,2,FALSE) -> 11f0adee-1845-2623-bd24-126156369a47 | I19: =VLOOKUP($B19,'All companies w Org IDs'!$A:$E,5,FALSE) -> BILLING | J19: 46037 | K19: 46051 | M19: CDK DMS FEE - ONE-TIME;SKAIVISION LITE (90 Day Renewal) ;CDK DMS FEE - MONTHLY | O19: SKAIVISION Customer Success | P19: Active - Healthy | Q19: 45946.833 | R19: Hollingsworth Richards Ford | S19: Dan Dillingham | T19: 1544 | U19: 3 Months | V19: 46113.566 | W19: 24539557269;2725529266;2673134739 | X19: 41957357645
A20: 51250024312 | B20: Toyota of Lake City | C20: Needs Jira Ticket | E20: Text Offer | F20: Tekion | G20: =VLOOKUP(B20,'All companies w Org IDs'!$A:$B,1,FALSE) -> Toyota of Lake city | H20: =VLOOKUP($B20,'All companies w Org IDs'!$A:$B,2,FALSE) -> 11f0e04e-f09c-1ec9-b23b-0affcfc7e79f | I20: =VLOOKUP($B20,'All companies w Org IDs'!$A:$E,5,FALSE) -> BILLING | J20: 46021 | K20: 46035 | M20: SKAIVISION LITE (12 Month Renewal);TEKION DMS FEE - MONTHLY | O20: SKAIVISION Customer Success | P20: Active - Healthy | Q20: 46013.528 | R20: Toyota of Lake city | S20: Blake Andreese | T20: 2700 | U20: 12 Months | V20: 46119.625 | W20: 2725529267;16369384749 | X20: 48183329204
A21: 52087766533 | B21: JLR North Dade | C21: Needs Jira Ticket | E21: Text Offer | F21: CDK | G21: =VLOOKUP(B21,'All companies w Org IDs'!$A:$B,1,FALSE) -> JLR North Dade | H21: =VLOOKUP($B21,'All companies w Org IDs'!$A:$B,2,FALSE) -> 11f0df45-05c9-82fa-b23b-0affcfc7e79f | I21: =VLOOKUP($B21,'All companies w Org IDs'!$A:$E,5,FALSE) -> BILLING | J21: 46013 | K21: 46027 | M21: SKAIVISION LITE (12 Month Renewal);CDK DMS FEE - MONTHLY;CDK DMS FEE - ONE-TIME | O21: SKAIVISION Customer Success | P21: Active - Healthy | Q21: 46012.792 | R21: JLR North Dade | S21: Mike Barnett | T21: 3488 | V21: 46120.556 | W21: 2725529267;2673134739;24539557269 | X21: 52360080809
A22: 52076957552 | B22: JLR South Dade | C22: Needs Jira Ticket | E22: Text Offer | F22: CDK | G22: =VLOOKUP(B22,'All companies w Org IDs'!$A:$B,1,FALSE) -> JLR South Dade | H22: =VLOOKUP($B22,'All companies w Org IDs'!$A:$B,2,FALSE) -> 11f0df44-941e-8d82-b23b-0affcfc7e79f | I22: =VLOOKUP($B22,'All companies w Org IDs'!$A:$E,5,FALSE) -> BILLING | J22: 46013 | K22: 46027 | M22: CDK DMS FEE - MONTHLY;SKAIVISION LITE (12 Month Renewal);CDK DMS FEE - ONE-TIME | O22: SKAIVISION Customer Success | P22: Active - Healthy | Q22: 46012.792 | R22: Land Rover South Dade;JLR South Dade | S22: Mike Barnett | T22: 3488 | V22: 46120.556 | W22: 2673134739;2725529267;24539557269 | X22: 47442310584;47442248718
A23: 50331770130 | B23: Universal Hyundai | C23: Needs Jira Ticket | E23: Text Offer | F23: Tekion | G23: =VLOOKUP(B23,'All companies w Org IDs'!$A:$B,1,FALSE) -> Universal Hyundai | H23: =VLOOKUP($B23,'All companies w Org IDs'!$A:$B,2,FALSE) -> 11f0df62-c5bb-aeef-b23b-0affcfc7e79f | I23: =VLOOKUP($B23,'All companies w Org IDs'!$A:$E,5,FALSE) -> BILLING | J23: 46013 | K23: 46015 | M23: SKAIVISION LITE (6 Month Renewal);TEKION DMS FEE - MONTHLY | O23: SKAIVISION Customer Success | P23: Active - Healthy | Q23: 46013.51 | R23: Universal Hyundai | S23: Mike Barnett | T23: 2300 | V23: 46113.376 | W23: 2725210928;16369384749 | X23: 26916209314
A24: 50331769863 | B24: Universal Nissan | C24: Needs Jira Ticket | E24: Text Offer | F24: Tekion | G24: =VLOOKUP(B24,'All companies w Org IDs'!$A:$B,1,FALSE) -> Universal Nissan | H24: =VLOOKUP($B24,'All companies w Org IDs'!$A:$B,2,FALSE) -> 11f0dabb-145e-4afc-b23b-0affcfc7e79f | I24: =VLOOKUP($B24,'All companies w Org IDs'!$A:$E,5,FALSE) -> BILLING | J24: 46013 | K24: 46014 | M24: SKAIVISION LITE (6 Month Renewal);TEKION DMS FEE - MONTHLY | O24: SKAIVISION Customer Success | P24: Active - Critical | Q24: 46007.554 | R24: Universal Nissan | S24: Mike Barnett | T24: 1150 | V24: 46113.376 | W24: 2725210928;16369384749 | X24: 26929411205
A25: 51020104040 | B25: Spokane Subaru | C25: Needs Jira Ticket | E25: Text Offer | F25: CDK | G25: =VLOOKUP(B25,'All companies w Org IDs'!$A:$B,1,FALSE) -> Spokane Subaru | H25: =VLOOKUP($B25,'All companies w Org IDs'!$A:$B,2,FALSE) -> 11f0d6dc-be30-e844-b23b-0affcfc7e79f | I25: =VLOOKUP($B25,'All companies w Org IDs'!$A:$E,5,FALSE) -> BILLING | J25: 46003 | K25: 46007 | M25: SKAIVISION LITE (12 Month Renewal);CDK DMS FEE - ONE-TIME;CDK DMS FEE - MONTHLY | O25: SKAIVISION Customer Success | P25: Active - Healthy | Q25: 46001.792 | R25: Spokane Subaru | S25: Blake Andreese | T25: 3188 | U25: 3 Months | V25: 46113.685 | W25: 2725529267;24539557269;2673134739 | X25: 50923715868
A26: 51075740476 | B26: James River Ford | C26: Needs Jira Ticket | E26: Text Offer | F26: CDK | G26: =VLOOKUP(B26,'All companies w Org IDs'!$A:$B,1,FALSE) -> James River Ford | H26: =VLOOKUP($B26,'All companies w Org IDs'!$A:$B,2,FALSE) -> 11f0d164-113e-1dce-b23b-0affcfc7e79f | I26: =VLOOKUP($B26,'All companies w Org IDs'!$A:$E,5,FALSE) -> BILLING | J26: 45996 | K26: 46010 | M26: CDK DMS FEE - ONE-TIME;CDK DMS FEE - MONTHLY;SKAIVISION LITE (90 Day Renewal) | N26: <a href="https://app.hubspot.com/contacts/22669654/record/0-2/46500025143 " target="_blank"> James River Auto </a> | O26: SKAIVISION Customer Success | P26: Active - Warning | Q26: 45995.695 | R26: James River Ford | S26: Dan Dillingham | T26: 1544 | U26: 3 Months | V26: 46112.642 | W26: 24539557269;2673134739;2725529266 | X26: 43749597969
A27: 51083599792 | B27: James River Chrysler Dodge Jeep RAM | C27: Needs Jira Ticket | E27: Text Offer | F27: CDK | G27: =VLOOKUP(B27,'All companies w Org IDs'!$A:$B,1,FALSE) -> James River Chrysler Dodge Jeep RAM | H27: =VLOOKUP($B27,'All companies w Org IDs'!$A:$B,2,FALSE) -> 11f0d164-8189-d8b1-b23b-0affcfc7e79 | I27: =VLOOKUP($B27,'All companies w Org IDs'!$A:$E,5,FALSE) -> BILLING | J27: 45996 | K27: 46008 | M27: CDK DMS FEE - MONTHLY;SKAIVISION LITE (6 Month Renewal);CDK DMS FEE - ONE-TIME | N27: <a href="https://app.hubspot.com/contacts/22669654/record/0-2/46500025143 " target="_blank"> James River Auto </a> | O27: SKAIVISION Customer Success | P27: Active - Warning | Q27: 45995.696 | R27: James River Chrysler Dodge Jeep RAM | S27: Dan Dillingham | T27: 3088 | U27: 3 Months | V27: 46113.376 | W27: 2673134739;2725210928;24539557269 | X27: 52982670465
A28: 49134754307 | B28: Chuck Nash Chevrolet Buick GMC | C28: Needs Jira Ticket | E28: Text Offer | F28: Tekion | G28: =VLOOKUP(B28,'All companies w Org IDs'!$A:$B,1,FALSE) -> Chuck Nash Chevrolet Buick GMC | H28: =VLOOKUP($B28,'All companies w Org IDs'!$A:$B,2,FALSE) -> 11f0c40c-f340-d7d0-b23b-0affcfc7e79f | I28: =VLOOKUP($B28,'All companies w Org IDs'!$A:$E,5,FALSE) -> CANCEL IN PROGRESS | J28: 45985 | K28: 45994 | M28: TEKION DMS FEE - MONTHLY;SKAIVISION LITE (90 Day Renewal) | O28: SKAIVISION Customer Success | P28: Active - Healthy | Q28: 45978.665 | R28: Chuck Nash Chevrolet Buick GMC | S28: Dan Dillingham | T28: 2700 | U28: 3 Months | V28: 46084.758 | W28: 16369384749;2725529266 | X28: 21254002526
A29: 45941512448 | B29: Howdy Honda | C29: Needs Jira Ticket | E29: Text Offer | F29: CDK | G29: =VLOOKUP(B29,'All companies w Org IDs'!$A:$B,1,FALSE) -> Howdy Honda | H29: =VLOOKUP($B29,'All companies w Org IDs'!$A:$B,2,FALSE) -> 11f0b699-6114-b201-afde-0affcfc7e79f | I29: =VLOOKUP($B29,'All companies w Org IDs'!$A:$E,5,FALSE) -> BILLING | J29: 45971 | K29: 45973 | M29: CDK DMS FEE - ONE-TIME;CDK DMS FEE - MONTHLY;SKAIVISION LITE (6 Month Renewal) | O29: SKAIVISION Customer Success | P29: Active - Warning | Q29: 45961.619 | R29: Howdy Honda | S29: Dan Dillingham | T29: 1644 | V29: 46113.375 | W29: 24539557269;2673134739;2725210928 | X29: 41577099128
A30: 46599389359 | B30: Longo Toyota of Prosper | C30: Needs Jira Ticket | E30: Text Offer | F30: Tekion | G30: =VLOOKUP(B30,'All companies w Org IDs'!$A:$B,1,FALSE) -> Longo Toyota of Prosper | H30: =VLOOKUP($B30,'All companies w Org IDs'!$A:$B,2,FALSE) -> 11f0b656-aacb-93c7-afde-0affcfc7e79f | I30: =VLOOKUP($B30,'All companies w Org IDs'!$A:$E,5,FALSE) -> BILLING | J30: 45967 | K30: 45971 | M30: TEKION DMS FEE - MONTHLY;SKAIVISION LITE (90 Day Renewal) | O30: SKAIVISION Customer Success | P30: Active - Healthy | Q30: 45961.527 | R30: Longo Toyota of Prosper | S30: Dan Dillingham | T30: 2700 | U30: 3 Months | V30: 46113.48 | W30: 16369384749;2725529266 | X30: 42223298487
A31: 45144986027 | B31: Stevens Creek Volkswagen | C31: Needs Jira Ticket | E31: Text Offer | F31: Tekion | G31: =VLOOKUP(B31,'All companies w Org IDs'!$A:$B,1,FALSE) -> Stevens Creek Volkswagen | H31: =VLOOKUP($B31,'All companies w Org IDs'!$A:$B,2,FALSE) -> 11f0a445-4f57-a8eb-bd24-126156369a47 | I31: =VLOOKUP($B31,'All companies w Org IDs'!$A:$E,5,FALSE) -> BILLING | J31: 45954 | K31: 45968 | M31: SKAIVISION LITE (12 Month Renewal);TEKION DMS FEE - MONTHLY | N31: <a href="https://app.hubspot.com/contacts/22669654/record/0-2/26934964504 " target="_blank"> American Motors Group </a> | O31: SKAIVISION Customer Success | P31: Active - Healthy | Q31: 45937.815 | R31: Stevens Creek Volkswagen | S31: Blake Andreese | T31: 1050 | V31: 46114.583 | W31: 2725529267;16369384749 | X31: 40833512060
A32: 45190982976 | B32: Volkswagen of Clovis | C32: Needs Jira Ticket | E32: Text Offer | F32: Tekion | G32: =VLOOKUP(B32,'All companies w Org IDs'!$A:$B,1,FALSE) -> Volkswagen of Clovis | H32: =VLOOKUP($B32,'All companies w Org IDs'!$A:$B,2,FALSE) -> 11f0a445-e1b5-243b-bd24-126156369a47 | I32: =VLOOKUP($B32,'All companies w Org IDs'!$A:$E,5,FALSE) -> BILLING | J32: 45954 | K32: 45961 | M32: TEKION DMS FEE - MONTHLY;SKAIVISION LITE (12 Month Renewal) | N32: <a href="https://app.hubspot.com/contacts/22669654/record/0-2/26934964504 " target="_blank"> American Motors Group </a> | O32: SKAIVISION Customer Success | P32: Active - Healthy | Q32: 45937.838 | R32: Volkswagen of Clovis | S32: Blake Andreese | T32: 1050 | U32: 12 Months | V32: 46114.583 | W32: 16369384749;2725529267 | X32: 40865235570
A33: 46041913616 | B33: Precision Honda | C33: Needs Jira Ticket | E33: Text Offer | F33: Tekion | G33: =VLOOKUP(B33,'All companies w Org IDs'!$A:$B,1,FALSE) -> Precision Honda | H33: =VLOOKUP($B33,'All companies w Org IDs'!$A:$B,2,FALSE) -> 11f0aab0-cd61-bd91-bd24-126156369a47 | I33: =VLOOKUP($B33,'All companies w Org IDs'!$A:$E,5,FALSE) -> BILLING | J33: 45947 | K33: 45959 | O33: SKAIVISION Customer Success | P33: Active - Healthy | Q33: 45944.833 | R33: Precision Honda | S33: Blake Andreese | T33: 2700 | V33: 46119.604 | X33: 41663550328
A34: 45476354320 | B34: Camp Chevrolet | C34: Needs Jira Ticket | E34: Text Offer; Cycle Time | F34: CDK | G34: =VLOOKUP(B34,'All companies w Org IDs'!$A:$B,1,FALSE) -> Camp Chevrolet | H34: =VLOOKUP($B34,'All companies w Org IDs'!$A:$B,2,FALSE) -> 11f0a44b-45b3-86e3-bd24-126156369a47 | I34: =VLOOKUP($B34,'All companies w Org IDs'!$A:$E,5,FALSE) -> IN PROGRESS (BILLING) | J34: 45943 | K34: 45952 | M34: SKAIVISION FULL (6 Month Renewal);CDK DMS FEE - MONTHLY;CDK DMS FEE - ONE-TIME | O34: SKAIVISION Onboarding Tracker | P34: Onboarding Cycle Times | Q34: 45938.351 | R34: Camp Chevrolet | S34: Blake Andreese | T34: 3288 | U34: 12 Months | V34: 46113.581 | W34: 2725210918;2673134739;24539557269 | X34: 41066374493
A35: 45417178115 | B35: Len Stoler Lexus Owings Mills | C35: Needs Jira Ticket | E35: Text Offer | F35: Tekion | G35: =VLOOKUP(B35,'All companies w Org IDs'!$A:$B,1,FALSE) -> Len Stoler Lexus Owings Mills | H35: =VLOOKUP($B35,'All companies w Org IDs'!$A:$B,2,FALSE) -> 11f0a3c4-3bce-5791-bd24-126156369a47 | I35: =VLOOKUP($B35,'All companies w Org IDs'!$A:$E,5,FALSE) -> CANCEL IN PROGRESS | J35: 45938 | K35: 45952 | M35: SKAIVISION LITE (90 Day Renewal) ;TEKION DMS FEE - MONTHLY | O35: SKAIVISION Customer Success | P35: Active - Healthy | Q35: 45937.715 | R35: Len Stoler Lexus Owings Mills | S35: Dan Dillingham | T35: 2100 | U35: 3 Months | V35: 46104.576 | W35: 2725529266;16369384749 | X35: 41056469612
A36: 43542892546 | B36: Jacksonville Kia | C36: Needs Jira Ticket | E36: Text Offer | F36: CDK | G36: =VLOOKUP(B36,'All companies w Org IDs'!$A:$B,1,FALSE) -> Jacksonville Kia | H36: =VLOOKUP($B36,'All companies w Org IDs'!$A:$B,2,FALSE) -> 11f08e6e-dc4e-0be7-bd24-126156369a47 | I36: =VLOOKUP($B36,'All companies w Org IDs'!$A:$E,5,FALSE) -> CANCEL IN PROGRESS | J36: 45910 | K36: 45922 | M36: CDK DMS FEE - ONE-TIME;CDK DMS FEE - MONTHLY;SKAIVISION LITE (6 Month Renewal) | O36: SKAIVISION Customer Success | P36: Active - Healthy | Q36: 45912.56 | R36: Jacksonville Kia | S36: Mike Barnett | T36: 1244 | V36: 46119.671 | W36: 24539557269;2673134739;2725210928 | X36: 39337844607
A37: 37634962826 | B37: Capital Hyundai of Greensboro | C37: Needs Jira Ticket | E37: Text Offer; Cycle Time | F37: CDK | G37: =VLOOKUP(B37,'All companies w Org IDs'!$A:$B,1,FALSE) -> Capital Hyundai of Greensboro | H37: =VLOOKUP($B37,'All companies w Org IDs'!$A:$B,2,FALSE) -> 11f0745e-bde4-b619-bd24-126156369a47 | I37: =VLOOKUP($B37,'All companies w Org IDs'!$A:$E,5,FALSE) -> BILLING | J37: 45910 | K37: 45933 | M37: CDK DMS FEE - ONE-TIME;SKAIVISION FULL (6 Month Renewal);CDK DMS FEE - MONTHLY | O37: SKAIVISION Customer Success | P37: Active - Healthy | Q37: 45897.544 | R37: Capital Hyundai Greensboro | S37: Mike Barnett | T37: 1244 | V37: 46119.671 | W37: 24539557269;2725210918;2673134739 | X37: 33840262281
A38: 43365449337 | B38: Lithia Nissan of Ames | C38: Needs Jira Ticket | E38: Text Offer | F38: CDK | G38: =VLOOKUP(B38,'All companies w Org IDs'!$A:$B,1,FALSE) -> Lithia Nissan of Ames | H38: =VLOOKUP($B38,'All companies w Org IDs'!$A:$B,2,FALSE) -> 11f089c8-2268-0e5a-bd24-126156369a47 | I38: =VLOOKUP($B38,'All companies w Org IDs'!$A:$E,5,FALSE) -> BILLING | J38: 45908 | M38: CDK DMS FEE - ONE-TIME;CDK DMS FEE - MONTHLY;SKAIVISION LITE (90 Day Renewal) | N38: <a href="https://app.hubspot.com/contacts/22669654/record/0-2/32973965400 " target="_blank"> Lithia Motors </a> | O38: SKAIVISION Customer Success | P38: Active - Healthy | Q38: 45903.833 | R38: Lithia Nissan of Ames | S38: Dan Dillingham | T38: 1644 | U38: 3 Months | V38: 46120.584 | W38: 24539557269;2673134739;2725529266 | X38: 39147107172
A39: 42069255341 | B39: Hyundai of Las Vegas | C39: Needs Jira Ticket | E39: Text Offer | F39: CDK | G39: =VLOOKUP(B39,'All companies w Org IDs'!$A:$B,1,FALSE) -> Hyundai of Las Vegas | H39: =VLOOKUP($B39,'All companies w Org IDs'!$A:$B,2,FALSE) -> 11f07d4f-ede6-c518-bd24-126156369a47 | I39: =VLOOKUP($B39,'All companies w Org IDs'!$A:$E,5,FALSE) -> BILLING | J39: 45894 | K39: 45908 | M39: CDK DMS FEE - ONE-TIME;SKAIVISION LITE (6 Month Renewal);CDK DMS FEE - MONTHLY | N39: <a href="https://app.hubspot.com/contacts/22669654/record/0-2/32973965400 " target="_blank"> Lithia Motors </a> | O39: SKAIVISION Customer Success | P39: Active - Healthy | Q39: 45883.833 | R39: Hyundai of Las Vegas | S39: Dan Dillingham | T39: 1344 | V39: 46118.613 | W39: 24539557269;2725210928;2673134739 | X39: 35011727106
A40: 41047003442 | B40: Vanguard GMC | C40: Needs Jira Ticket | E40: Text Offer | F40: Tekion | G40: =VLOOKUP(B40,'All companies w Org IDs'!$A:$B,1,FALSE) -> Vanguard GMC | H40: =VLOOKUP($B40,'All companies w Org IDs'!$A:$B,2,FALSE) -> 11f06d73-3e90-692b-bd24-126156369a47 | I40: =VLOOKUP($B40,'All companies w Org IDs'!$A:$E,5,FALSE) -> CANCEL IN PROGRESS | J40: 45870 | K40: 45877 | M40: SKAIVISION LITE (90 Day Renewal) ;TEKION DMS FEE - MONTHLY | O40: SKAIVISION Customer Success | P40: Churn - Cancelation Requested | Q40: 45867.833 | R40: Vanguard GMC | S40: Dan Dillingham | T40: 2700 | U40: 3 Months | V40: 46101.479 | W40: 2725529266;16369384749 | X40: 36964799869
...

Sheet All companies w Org IDs
A1: Company name | B1: Skai Org ID Long | C1: Record ID | D1: Create Date | E1: Status | F1: Dealer Group (Archived) | G1: Billing Start Date | H1: SKAI Products | I1: Type | J1: Phone Number | K1: Last Activity Date | L1: City | M1: Country/Region | N1: Industry | O1: Associated Company | P1: Associated Contact | Q1: Skai Org ID Long | R1: Skai Org ID Short | S1: Associated Company IDs | T1: Associated Contact IDs
C2: 53736258935 | D2: 46118.604 | P2: HUBSPOT: AutoNation Toyota Cerritos (hubspot+autonationtoyotacerritos@skaivision.net);HUBSPOT: Culver City Honda (hubspot+culvercityhonda@skaivision.net);HUBSPOT: LEGACY CHEVROLET OF WAXAHACHIE (hubspot+legacychevroletofwaxahachie@skaivision.net);HUBSPOT: Dave Sinclair Lincoln St. Peters (hubspot+davesinclairlincolnstpeters@skaivision.net);HUBSPOT: Dave Sinclair Lincoln (hubspot+davesinclairlincoln@skaivision.net);HUBSPOT: Ed Voyles Honda (hubspot+edvoyleshonda@skaivision.net) | T2: 214447497319;214459198782;214402242159;214405035018;214151861809;213956590420
C3: 53729637304 | D3: 46115.734 | K3: 46120.446 | P3: Cameron Metreaud (documents@esign.dealerbuilt.com) | T3: 213569420160
C4: 53543071138 | D4: 46112.594 | K4: 46112.929 | P4: andrew@morganautogroupo.com | T4: 212805834559
C5: 53303087277 | D5: 46107.31 | P5: Jon Munzel (jon@autotlsummits.com) | T5: 211722169152
C6: 53102453672 | D6: 46100.485 | L6: Highland Charter Township | M6: United States | P6: Ryan Benard (ryan@lafontaineauto.com) | T6: 210347311712
C7: 53091610544 | D7: 46099.622 | J7: +14178823838 | K7: 46118.534 | P7: Jeffrey Mindock (jmindock@springfield-auto.com) | T7: 210107115281
C8: 53009716521 | D8: 46098.924 | J8: +17084443200 | K8: 46118.475 | L8: Orland Park | M8: United States | P8: Jack Howe (jhowe@mazdaoforlandpark.com) | T8: 209957355899
C9: 53007388574 | D9: 46098.795 | P9: Newsletter (skaivision-com@inbound.godigitalpigeon.com) | T9: 209923843619
C10: 53004009220 | D10: 46097.908 | J10: +14704652886 | P10: David Metter (david@kenektr.com) | T10: 207270937241
C11: 52913857903 | D11: 46093.804 | K11: 46094.668 | P11: Ty Oberly (toberly@premierofcarlsbad.com) | T11: 208903337506
C12: 52594189136 | D12: 46087.433 | K12: 46087.434 | P12: Matthew Verost (mverost@myrtlbeachautomotive.com) | T12: 207498291007
C13: 52556941149 | D13: 46085.483 | J13: +15046673006 | K13: 46113.581 | P13: Michael Kuhn (mkuhn@rayautogroup.com) | T13: 207013505907
C14: 52511674649 | D14: 46084.551 | J14: +18555891800 | K14: 46115.637 | P14: Red Capistrano (red@bdcautomation.com);Ash Kifle (ash@bdcautomation.com) | T14: 207348744078;206740825449
C15: 52183490875 | D15: 46080.512 | K15: 46105.718 | P15: Grant Daniel (grant@intra-comm.net) | T15: 205765202223
C16: 52205811633 | D16: 46080.492 | K16: 46091.521 | N16: Financial Services | P16: Richard Vaucher (vaucher.r@2bnice-finance.com) | T16: 205876058526
C17: 51976050315 | D17: 46077.608 | K17: 46078.542 | P17: Tova Miller (tova.m@datalogicprovider.com) | T17: 205139054909
C18: 51895399556 | D18: 46075.451 | K18: 46111.403 | P18: Angela Hastings (angelah@gowinnerscircle.com);Jarryd Carver (jarrydc@gowinnerscircle.com) | T18: 211388576860;204396033338
C19: 51657874221 | D19: 46073.265 | P19: Luka Secilmis (s-luka@demobrowser-use.com);Magnus Müller (magnus.m@demobrowser-use.com) | T19: 213433254777;204085666823
C20: 51542039735 | D20: 46070.551 | K20: 46077.417 | P20: Donavan Lett (dlett@msbhv.com) | T20: 203328628287
C21: 51308227433 | D21: 46066.621 | J21: +19703393900 | P21: scott@mcdonaldautomotive.com | T21: 202156959325
C22: 51306329001 | D22: 46066.621 | J22: +16787832700 | P22: Kevin Deutsch (kevin@butlerlsa.com) | T22: 202143530611
C23: 51305864270 | D23: 46066.621 | P23: Yuhei Hatano (yuhei_hatano@na.honda.com) | T23: 202143841090
C24: 51311591534 | D24: 46066.621 | P24: msurey@gladstonedcjr.com | T24: 202157578635
C25: 51302147997 | D25: 46066.621 | K25: 46115.677 | P25: Adam Dzasim (adamdzasim@uftringmontgomery.com);Brad Montgomery (bradmontgomery@uftringmontgomery.com) | T25: 213088339726;202127781744
C26: 51319953229 | D26: 46066.621 | J26: +15136799160 | P26: jake@mccluskey.com;mccluskeyc@mccluskey.com | T26: 202136099072;202121744960
C27: 51185745211 | D27: 46064.512 | P27: Mark Mears (mmears@parkway-honda.com) | T27: 201457364865
C28: 50935722826 | D28: 46062.639 | P28: Brian Sather (brian@briansather.net) | T28: 200720828315
C29: 50926393765 | D29: 46062.632 | K29: 46092.555 | P29: Bryan Toler (loans@bendcable.com) | T29: 200672583084
C30: 50195330841 | D30: 46051.56 | K30: 46051.561 | P30: Bernie Black (bblack@shottenkirkhyundairome.net) | T30: 197522758311
C31: 50195020397 | D31: 46051.549 | P31: Brittany Lewis (blewis@shottenkirkhondacartersville.org) | T31: 197523249458
C32: 50100952601 | D32: 46051.481 | K32: 46082.376 | P32: Norma Woodward (nwoodward@frontroyalbuickgmc.co) | T32: 197523180156
C33: 49858749616 | D33: 46049.658 | J33: +14087097006 | K33: 46079.667 | P33: alan.le@capitolnissansj.com;raffy.pangilinan@capitolnissansj.com;eric.lam@capitolnissansj.com | T33: 196767980622;196767983649;196782942058
C34: 49748736826 | D34: 46048.613
C35: 49447857424 | D35: 46043.664 | P35: Assane Faye (afaye@berkshirehathawayauto.com) | T35: 195052192567
C36: 49379690169 | D36: 46042.681 | J36: +17278355654 | P36: Ken Marks (kmarks@coastbgm.com) | T36: 194730992705
C37: 49442084759 | D37: 46042.681 | J37: +14132876869 | L37: Los Angeles | M37: United States | N37: Automotive | P37: Carla Cosenzi (carla@tommycarmgt.com) | T37: 194733314706
C38: 49441125957 | D38: 46042.681 | P38: Peter Larson (peter.larson@manchester-honda.com) | T38: 194736060972
C39: 49298299945 | D39: 46042.681 | J39: +12037937642 | P39: Neil Rosenstein (csr@buy-auto.com) | T39: 194729410866
C40: 49281646472 | D40: 46042.681 | J40: +18323737322 | P40: Selcuk Kaya (selcuk@kayalar-motors.com) | T40: 194733314702
...
